Workbook

Sheet Hierarquia
A1: ID | B1: Nome | C1: Tipo | D1: ID Pai | E1: ID Supervisão | F1: Nome Exibição | G1: data criação | H1: Ativa? | I1: proxima multiplicação
A2: 1 | B2: Arca Church | C2: Igreja | F2: =UPPER(B2) -> ARCA CHURCH | G2: - | H2: Sim | I2: -
A3: 2 | B3: SHALOM | C3: Supervisão | D3: 1 | E3: 2 | F3: =UPPER(B3) -> SHALOM | G3: - | H3: Sim | I3: -
A4: 3 | B4: CORDATUS | C4: Supervisão | D4: 2 | E4: 3 | F4: =UPPER(B4) -> CORDATUS | G4: - | H4: Sim | I4: -
A5: 4 | B5: ABA PAI | C5: Supervisão | D5: 2 | E5: 4 | F5: =UPPER(B5) -> ABA PAI | G5: - | H5: Sim | I5: -
A6: 5 | B6: Além do Véu | C6: Supervisão | D6: 2 | E6: 5 | F6: =UPPER(B6) -> ALÉM DO VÉU | G6: - | H6: Sim | I6: -
A7: 6 | B7: BETESDA | C7: Supervisão | D7: 2 | E7: 6 | F7: =UPPER(B7) -> BETESDA | G7: - | H7: Sim | I7: -
A8: 7 | B8: Dunamis | C8: Supervisão | D8: 2 | E8: 7 | F8: =UPPER(B8) -> DUNAMIS | G8: - | H8: Sim | I8: -
A9: 8 | B9: OUTSIDE | C9: Supervisão | D9: 2 | E9: 8 | F9: =UPPER(B9) -> OUTSIDE | G9: - | H9: Sim | I9: -
A10: 9 | B10: Transformação | C10: Supervisão | D10: 3 | E10: 9 | F10: =UPPER(B10) -> TRANSFORMAÇÃO | G10: - | H10: Sim | I10: -
A11: 10 | B11: TSALEACH | C11: Supervisão | D11: 2 | E11: 10 | F11: =UPPER(B11) -> TSALEACH | G11: - | H11: Sim | I11: -
A12: 11 | B12: ABA PAI | C12: Célula | D12: 4 | E12: 4 | F12: =UPPER(B12) -> ABA PAI | G12: =IF(C12="Célula",VLOOKUP(B12,'Página2'!A:B,2,FALSE)) -> 45412.69 | H12: Não | I12: =IF(C12="Célula",VLOOKUP(B12,Planilha1!A:B,2,FALSE),"") -> 45962
A13: 12 | B13: ADONAI | C13: Célula | D13: 11 | E13: 4 | F13: =UPPER(B13) -> ADONAI | G13: =IF(C13="Célula",VLOOKUP(B13,'Página2'!A:B,2,FALSE)) -> 45146.543 | H13: Não | I13: =IF(C13="Célula",VLOOKUP(B13,Planilha1!A:B,2,FALSE),"") -> Desativada
A14: 13 | B14: AHAVA | C14: Célula | D14: 11 | E14: 4 | F14: =UPPER(B14) -> AHAVA | G14: =IF(C14="Célula",VLOOKUP(B14,'Página2'!A:B,2,FALSE)) -> 45164.769 | H14: Sim | I14: =IF(C14="Célula",VLOOKUP(B14,Planilha1!A:B,2,FALSE),"") -> 46327
A15: 14 | B15: Chedvah | C15: Célula | D15: 11 | E15: 4 | F15: =UPPER(B15) -> CHEDVAH | G15: =IF(C15="Célula",VLOOKUP(B15,'Página2'!A:B,2,FALSE)) -> 45749.749 | H15: Sim | I15: =IF(C15="Célula",VLOOKUP(B15,Planilha1!A:B,2,FALSE),"") -> 46327
A16: 15 | B16: EBENÉZER | C16: Célula | D16: 11 | E16: 4 | F16: =UPPER(B16) -> EBENÉZER | G16: =IF(C16="Célula",VLOOKUP(B16,'Página2'!A:B,2,FALSE)) -> 45161.051 | H16: Sim | I16: =IF(C16="Célula",VLOOKUP(B16,Planilha1!A:B,2,FALSE),"") -> 46357
A17: 16 | B17: MELEAH | C17: Célula | D17: 23 | E17: 4 | F17: =UPPER(B17) -> MELEAH | G17: =IF(C17="Célula",VLOOKUP(B17,'Página2'!A:B,2,FALSE)) -> 46134.738 | H17: Sim | I17: =IF(C17="Célula",VLOOKUP(B17,Planilha1!A:B,2,FALSE),"") -> 46499
A18: 17 | B18: Mōriyāh | C18: Célula | D18: 15 | E18: 4 | F18: =UPPER(B18) -> MŌRIYĀH | G18: =IF(C18="Célula",VLOOKUP(B18,'Página2'!A:B,2,FALSE)) -> 46002.63 | H18: Sim | I18: =IF(C18="Célula",VLOOKUP(B18,Planilha1!A:B,2,FALSE),"") -> 46357
A19: 18 | B19: Novo Começo | C19: Célula | D19: 11 | E19: 4 | F19: =UPPER(B19) -> NOVO COMEÇO | G19: =IF(C19="Célula",VLOOKUP(B19,'Página2'!A:B,2,FALSE)) -> 45618.617 | H19: Não | I19: =IF(C19="Célula",VLOOKUP(B19,Planilha1!A:B,2,FALSE),"") -> Desativada
A20: 19 | B20: Peniel | C20: Célula | D20: 11 | E20: 4 | F20: =UPPER(B20) -> PENIEL | G20: =IF(C20="Célula",VLOOKUP(B20,'Página2'!A:B,2,FALSE)) -> 45789.441 | H20: Não | I20: =IF(C20="Célula",VLOOKUP(B20,Planilha1!A:B,2,FALSE),"") -> 46174
A21: 20 | B21: RAFAH | C21: Célula | D21: 11 | E21: 4 | F21: =UPPER(B21) -> RAFAH | G21: =IF(C21="Célula",VLOOKUP(B21,'Página2'!A:B,2,FALSE)) -> 45813.45 | H21: Não | I21: =IF(C21="Célula",VLOOKUP(B21,Planilha1!A:B,2,FALSE),"") -> 46174
A22: 21 | B22: RECOMEÇAR | C22: Célula | D22: 19 | E22: 4 | F22: =UPPER(B22) -> RECOMEÇAR | G22: =IF(C22="Célula",VLOOKUP(B22,'Página2'!A:B,2,FALSE)) -> 45146.548 | H22: Sim | I22: =IF(C22="Célula",VLOOKUP(B22,Planilha1!A:B,2,FALSE),"") -> 46174
A23: 22 | B23: REDENÇÃO | C23: Célula | D23: 11 | E23: 4 | F23: =UPPER(B23) -> REDENÇÃO | G23: =IF(C23="Célula",VLOOKUP(B23,'Página2'!A:B,2,FALSE)) -> 45962.398 | H23: Sim | I23: =IF(C23="Célula",VLOOKUP(B23,Planilha1!A:B,2,FALSE),"") -> 46327
... A33: 32 | B33: ZAYA | C33: Célula | D33: 26 | E33: 6 | F33: =UPPER(B33) -> ZAYA | G33: =IF(C33="Célula",VLOOKUP(B33,'Página2'!A:B,2,FALSE)) -> 45227.855 | H33: Sim | I33: =IF(C33="Célula",VLOOKUP(B33,Planilha1!A:B,2,FALSE),"") -> 46266
A34: 33 | B34: ASAH | C34: Célula | E34: 3 | F34: =UPPER(B34) -> ASAH | G34: =IF(C34="Célula",VLOOKUP(B34,'Página2'!A:B,2,FALSE)) -> 45827.378 | H34: Não | I34: =IF(C34="Célula",VLOOKUP(B34,Planilha1!A:B,2,FALSE),"") -> 46204
A35: 34 | B35: DHARA | C35: Célula | E35: 3 | F35: =UPPER(B35) -> DHARA | G35: =IF(C35="Célula",VLOOKUP(B35,'Página2'!A:B,2,FALSE)) -> 45574.336 | H35: Sim | I35: =IF(C35="Célula",VLOOKUP(B35,Planilha1!A:B,2,FALSE),"") -> 46220
A36: 35 | B36: ELCANA | C36: Célula | E36: 3 | F36: =UPPER(B36) -> ELCANA | G36: =IF(C36="Célula",VLOOKUP(B36,'Página2'!A:B,2,FALSE)) -> 45856.613 | H36: Não | I36: =IF(C36="Célula",VLOOKUP(B36,Planilha1!A:B,2,FALSE),"") -> 46220
A37: 36 | B37: KADIMA | C37: Célula | E37: 3 | F37: =UPPER(B37) -> KADIMA | G37: =IF(C37="Célula",VLOOKUP(B37,'Página2'!A:B,2,FALSE)) -> 45146.556 | H37: Sim | I37: =IF(C37="Célula",VLOOKUP(B37,Planilha1!A:B,2,FALSE),"") -> 46174
A38: 37 | B38: KADOSH | C38: Célula | E38: 3 | F38: =UPPER(B38) -> KADOSH | G38: =IF(C38="Célula",VLOOKUP(B38,'Página2'!A:B,2,FALSE)) -> 46000.943 | H38: Sim | I38: =IF(C38="Célula",VLOOKUP(B38,Planilha1!A:B,2,FALSE),"") -> 46357
A39: 38 | B39: MERGULHADOS EM CRISTO | C39: Célula | E39: 3 | F39: =UPPER(B39) -> MERGULHADOS EM CRISTO | G39: =IF(C39="Célula",VLOOKUP(B39,'Página2'!A:B,2,FALSE)) -> 45271.824 | H39: Sim | I39: =IF(C39="Célula",VLOOKUP(B39,Planilha1!A:B,2,FALSE),"") -> 46357
A40: 39 | B40: RENOVAÇÃO | C40: Célula | E40: 3 | F40: =UPPER(B40) -> RENOVAÇÃO | G40: =IF(C40="Célula",VLOOKUP(B40,'Página2'!A:B,2,FALSE)) -> #N/A | H40: Não | I40: =IF(C40="Célula",VLOOKUP(B40,Planilha1!A:B,2,FALSE),"") -> #N/A
A41: 40 | B41: RESGATE | C41: Célula | D41: 42 | E41: 3 | F41: =UPPER(B41) -> RESGATE | G41: =IF(C41="Célula",VLOOKUP(B41,'Página2'!A:B,2,FALSE)) -> 45172.782 | H41: Não | I41: =IF(C41="Célula",VLOOKUP(B41,Planilha1!A:B,2,FALSE),"") -> 46204
A42: 41 | B42: SOPRO DE VIDA | C42: Célula | D42: 38 | E42: 3 | F42: =UPPER(B42) -> SOPRO DE VIDA | G42: =IF(C42="Célula",VLOOKUP(B42,'Página2'!A:B,2,FALSE)) -> 45567.641 | H42: Sim | I42: =IF(C42="Célula",VLOOKUP(B42,Planilha1!A:B,2,FALSE),"") -> 45931
A43: 42 | B43: YATSA | C43: Célula | D43: 72 | E43: 3 | F43: =UPPER(B43) -> YATSA | G43: =IF(C43="Célula",VLOOKUP(B43,'Página2'!A:B,2,FALSE)) -> 45146.558 | H43: não | I43: =IF(C43="Célula",VLOOKUP(B43,Planilha1!A:B,2,FALSE),"") -> 46082
A44: 43 | B44: Betel | C44: Célula | E44: 7 | F44: =UPPER(B44) -> BETEL | G44: =IF(C44="Célula",VLOOKUP(B44,'Página2'!A:B,2,FALSE)) -> 45745.642 | H44: Sim | I44: =IF(C44="Célula",VLOOKUP(B44,Planilha1!A:B,2,FALSE),"") -> 46478
A45: 44 | B45: CANDEEIRO | C45: Célula | E45: 7 | F45: =UPPER(B45) -> CANDEEIRO | G45: =IF(C45="Célula",VLOOKUP(B45,'Página2'!A:B,2,FALSE)) -> 45531.908 | H45: Sim | I45: =IF(C45="Célula",VLOOKUP(B45,Planilha1!A:B,2,FALSE),"") -> 46296
A46: 45 | B46: DUNAMIS | C46: Célula | E46: 7 | F46: =UPPER(B46) -> DUNAMIS | G46: =IF(C46="Célula",VLOOKUP(B46,'Página2'!A:B,2,FALSE)) -> 45161.047 | H46: Sim | I46: =IF(C46="Célula",VLOOKUP(B46,Planilha1!A:B,2,FALSE),"") -> 46327
A47: 46 | B47: Elohim | C47: Célula | E47: 7 | F47: =UPPER(B47) -> ELOHIM | G47: =IF(C47="Célula",VLOOKUP(B47,'Página2'!A:B,2,FALSE)) -> #N/A | H47: Sim | I47: =IF(C47="Célula",VLOOKUP(B47,Planilha1!A:B,2,FALSE),"") -> #N/A
A48: 47 | B48: LEÃO DE JUDÁ | C48: Célula | E48: 7 | F48: =UPPER(B48) -> LEÃO DE JUDÁ | G48: =IF(C48="Célula",VLOOKUP(B48,'Página2'!A:B,2,FALSE)) -> 45971.778 | H48: Sim | I48: =IF(C48="Célula",VLOOKUP(B48,Planilha1!A:B,2,FALSE),"") -> 46327
A49: 48 | B49: Nahar | C49: Célula | E49: 7 | F49: =UPPER(B49) -> NAHAR | G49: =IF(C49="Célula",VLOOKUP(B49,'Página2'!A:B,2,FALSE)) -> 45932.413 | H49: Sim | I49: =IF(C49="Célula",VLOOKUP(B49,Planilha1!A:B,2,FALSE),"") -> 46296
...

Sheet Página2
A1: Nome da Célula | B1: Data de Criação
A2: ABAB | B2: 45901.692
A3: ABA PAI | B3: 45412.69
A4: ADONAI | B4: 45146.543
A5: A FORJA | B5: 45709.392
A6: ÁGAPE | B6: 45512.309
A7: AHAVA | B7: 45164.769
A8: ALÉM DO VÉU | B8: 45161.059
A9: ASAH | B9: 45827.378
A10: ATOS | B10: 45772.831
A11: BARAK | B11: 46112.342
A12: BENJAMIM | B12: 45161.047
A13: Betel | B13: 45745.642
... A62: ZERA | B62: 45971.781

Sheet Planilha1
A1: CÉLULA | B1: Data Multiplicação | C1: data cadastro
A2: BENJAMIM | B2: 45870
A3: Haja Luz | B3: 46327
A4: Ágape | B4: 46204
A5: Zaya | B5: 46266
A6: Moriá | B6: 45901
A7: Resgate | B7: 46204
A8: Candeeiro | B8: 46296
A9: DUNAMIS | B9: 46327
A10: Os Escolhidos | B10: 46478
A11: Kadima | B11: 46174
A12: Videira | B12: 46140
A13: Dhara | B13: 46220
... A38: RECOMEÇAR | B38: 46174
A39: YESHUA | B39: Desativada
A40: Adonai | B40: Desativada
A41: Impactados | B41: Desativada
A42: KAIRÓS | B42: Desativada
A43: Novo Começo | B43: Desativada
A44: RAFAH | B44: 46174
A45: Célulanova 2 | B45: 46174
A46: RENASCER | B46: 46266
A47: ASAH | B47: 46204
A48: BOA PARTE | B48: 46204
A49: Reset | B49: 46478
A50: ELCANA | B50: 46220
A51: ABAB | B51: 46266
A52: ABIMAEL | B52: 46266
A53: NAHAR | B53: 46296
A54: FORTALEZA DE SIÂO | B54: 46478
A55: ZERA | B55: 46499
... A71: Hamakon Kadosh | B71: 46505
